Traceback (most recent call last):
  File "/Users/robinkuipers/anaconda3/lib/python3.10/site-packages/jupyter_cache/executors/utils.py", line 58, in single_nb_execution
    executenb(
  File "/Users/robinkuipers/anaconda3/lib/python3.10/site-packages/nbclient/client.py", line 1204, in execute
    return NotebookClient(nb=nb, resources=resources, km=km, **kwargs).execute()
  File "/Users/robinkuipers/anaconda3/lib/python3.10/site-packages/nbclient/util.py", line 84, in wrapped
    return just_run(coro(*args, **kwargs))
  File "/Users/robinkuipers/anaconda3/lib/python3.10/site-packages/nbclient/util.py", line 62, in just_run
    return loop.run_until_complete(coro)
  File "/Users/robinkuipers/anaconda3/lib/python3.10/asyncio/base_events.py", line 649, in run_until_complete
    return future.result()
  File "/Users/robinkuipers/anaconda3/lib/python3.10/site-packages/nbclient/client.py", line 663, in async_execute
    await self.async_execute_cell(
  File "/Users/robinkuipers/anaconda3/lib/python3.10/site-packages/nbclient/client.py", line 965, in async_execute_cell
    await self._check_raise_for_error(cell, cell_index, exec_reply)
  File "/Users/robinkuipers/anaconda3/lib/python3.10/site-packages/nbclient/client.py", line 862, in _check_raise_for_error
    raise CellExecutionError.from_cell_and_msg(cell, exec_reply_content)
nbclient.exceptions.CellExecutionError: An error occurred while executing the following cell:
------------------

colors = ['rgb(102,194,165)', 'rgb(252,141,98)', 'rgb(141,160,203)']


layout = go.Layout(
    xaxis=go.layout.XAxis(
        type='category',  # The x-axis type is categorical
        tickvals=['2020', '2022'],  # Set custom tick values
        ticktext=['2020', '2022'],  # Set custom tick labels
    ),

    width=600,
    height=600
)

data = []
for country in inflation2020['LOCATION'].unique():
    # Extract the data for each country
    country_data_2020 = inflation2020[inflation2020['LOCATION'] == country]
    country_data_2022 = inflation2022[inflation2022['LOCATION'] == country]
    
    # Create a trace for each country
    trace = go.Scatter(
        x=['2020', '2022'],
        y=[country_data_2020['Value'].iloc[0], country_data_2022['Value'].iloc[0]],
        mode='lines+markers',
        name=country,
#         
    )
    
    data.append(trace)


fig = go.Figure(data=data, layout=layout)


fig.update_layout(
    title="Inflation Rates by Country with the year 2015 as inflation rate 100",
    xaxis_title="Year",
    yaxis_title="Inflation Rate",
)


fig.show()

------------------

[0;31m---------------------------------------------------------------------------[0m
[0;31mIndexError[0m                                Traceback (most recent call last)
Cell [0;32mIn[8], line 24[0m
[1;32m     19[0m     country_data_2022 [38;5;241m=[39m inflation2022[inflation2022[[38;5;124m'[39m[38;5;124mLOCATION[39m[38;5;124m'[39m] [38;5;241m==[39m country]
[1;32m     21[0m     [38;5;66;03m# Create a trace for each country[39;00m
[1;32m     22[0m     trace [38;5;241m=[39m go[38;5;241m.[39mScatter(
[1;32m     23[0m         x[38;5;241m=[39m[[38;5;124m'[39m[38;5;124m2020[39m[38;5;124m'[39m, [38;5;124m'[39m[38;5;124m2022[39m[38;5;124m'[39m],
[0;32m---> 24[0m         y[38;5;241m=[39m[country_data_2020[[38;5;124m'[39m[38;5;124mValue[39m[38;5;124m'[39m][38;5;241m.[39miloc[[38;5;241m0[39m], [43mcountry_data_2022[49m[43m[[49m[38;5;124;43m'[39;49m[38;5;124;43mValue[39;49m[38;5;124;43m'[39;49m[43m][49m[38;5;241;43m.[39;49m[43miloc[49m[43m[[49m[38;5;241;43m0[39;49m[43m][49m],
[1;32m     25[0m         mode[38;5;241m=[39m[38;5;124m'[39m[38;5;124mlines+markers[39m[38;5;124m'[39m,
[1;32m     26[0m         name[38;5;241m=[39mcountry,
[1;32m     27[0m [38;5;66;03m#         [39;00m
[1;32m     28[0m     )
[1;32m     30[0m     data[38;5;241m.[39mappend(trace)
[1;32m     33[0m fig [38;5;241m=[39m go[38;5;241m.[39mFigure(data[38;5;241m=[39mdata, layout[38;5;241m=[39mlayout)

File [0;32m~/anaconda3/lib/python3.10/site-packages/pandas/core/indexing.py:1073[0m, in [0;36m_LocationIndexer.__getitem__[0;34m(self, key)[0m
[1;32m   1070[0m axis [38;5;241m=[39m [38;5;28mself[39m[38;5;241m.[39maxis [38;5;129;01mor[39;00m [38;5;241m0[39m
[1;32m   1072[0m maybe_callable [38;5;241m=[39m com[38;5;241m.[39mapply_if_callable(key, [38;5;28mself[39m[38;5;241m.[39mobj)
[0;32m-> 1073[0m [38;5;28;01mreturn[39;00m [38;5;28;43mself[39;49m[38;5;241;43m.[39;49m[43m_getitem_axis[49m[43m([49m[43mmaybe_callable[49m[43m,[49m[43m [49m[43maxis[49m[38;5;241;43m=[39;49m[43maxis[49m[43m)[49m

File [0;32m~/anaconda3/lib/python3.10/site-packages/pandas/core/indexing.py:1625[0m, in [0;36m_iLocIndexer._getitem_axis[0;34m(self, key, axis)[0m
[1;32m   1622[0m     [38;5;28;01mraise[39;00m [38;5;167;01mTypeError[39;00m([38;5;124m"[39m[38;5;124mCannot index by location index with a non-integer key[39m[38;5;124m"[39m)
[1;32m   1624[0m [38;5;66;03m# validate the location[39;00m
[0;32m-> 1625[0m [38;5;28;43mself[39;49m[38;5;241;43m.[39;49m[43m_validate_integer[49m[43m([49m[43mkey[49m[43m,[49m[43m [49m[43maxis[49m[43m)[49m
[1;32m   1627[0m [38;5;28;01mreturn[39;00m [38;5;28mself[39m[38;5;241m.[39mobj[38;5;241m.[39m_ixs(key, axis[38;5;241m=[39maxis)

File [0;32m~/anaconda3/lib/python3.10/site-packages/pandas/core/indexing.py:1557[0m, in [0;36m_iLocIndexer._validate_integer[0;34m(self, key, axis)[0m
[1;32m   1555[0m len_axis [38;5;241m=[39m [38;5;28mlen[39m([38;5;28mself[39m[38;5;241m.[39mobj[38;5;241m.[39m_get_axis(axis))
[1;32m   1556[0m [38;5;28;01mif[39;00m key [38;5;241m>[39m[38;5;241m=[39m len_axis [38;5;129;01mor[39;00m key [38;5;241m<[39m [38;5;241m-[39mlen_axis:
[0;32m-> 1557[0m     [38;5;28;01mraise[39;00m [38;5;167;01mIndexError[39;00m([38;5;124m"[39m[38;5;124msingle positional indexer is out-of-bounds[39m[38;5;124m"[39m)

[0;31mIndexError[0m: single positional indexer is out-of-bounds
IndexError: single positional indexer is out-of-bounds

